Workbook
Name in_id: 'Input'!$B$6
Name in_p: 'Input'!$B$11
Name in_H: 'Input'!$B$12
Name in_t: 'Input'!$B$13
Name in_mode: 'Input'!$B$14
Name in_Rc: 'Input'!$B$15
Name in_Rv: 'Input'!$B$16
Name in_alpha: 'Input'!$B$17
Name in_dims: 'Input'!$B$18
Name in_pitchref: 'Input'!$B$19
Name in_beta: 'Input'!$B$23
Name in_betaref: 'Input'!$B$24
Name in_E: 'Input'!$B$29
Name in_nu: 'Input'!$B$30
Name in_rho: 'Input'!$B$31
Name in_tmin: 'Input'!$B$32
Name in_CA: 'Input'!$B$33
Name in_Sallow: 'Input'!$B$34
Name lc_name: 'Input'!$B$38
Name lc_axes: 'Input'!$B$39
Name lc_zone: 'Input'!$B$40
Name lc_Nx: 'Input'!$B$41
Name lc_Ny: 'Input'!$B$42
Name lc_Nxy: 'Input'!$B$43
Name lc_Mx: 'Input'!$B$44
Name lc_My: 'Input'!$B$45
Name lc_Mxy: 'Input'!$B$46
Name lc_allow: 'Input'!$B$47
Name beta_deg: 'Geometry'!$B$6
Name beta: 'Geometry'!$B$7
Name p_: 'Geometry'!$B$8
Name H_mid: 'Geometry'!$B$9
Name h_calc: 'Geometry'!$B$10
Name c_: 'Geometry'!$B$11
Name f_: 'Geometry'!$B$12
Name Rc_in: 'Geometry'!$B$16
Name Rv_in: 'Geometry'!$B$17
Name Rs: 'Geometry'!$B$18
Name a_hi: 'Geometry'!$B$19
Name alpha_A: 'Geometry'!$B$44
Name resid_A: 'Geometry'!$B$45
Name alpha_B: 'Geometry'!$B$46
Name R_B: 'Geometry'!$B$47
Name alpha: 'Geometry'!$B$48
Name alpha_deg: 'Geometry'!$B$49
Name Rc: 'Geometry'!$B$50
Name Rv: 'Geometry'!$B$51
Name TL: 'Geometry'!$B$52
Name Rmin: 'Geometry'!$B$53
Name chk_geom: 'Geometry'!$B$54
Name l_: 'Geometry'!$B$58
Name lam: 'Geometry'!$B$59
Name q_int: 'Geometry'!$B$60
Name I_1: 'Geometry'!$B$61
Name a_c: 'Geometry'!$B$62
Name a_v: 'Geometry'!$B$63
Name z_1: 'Geometry'!$B$64
Name z_2: 'Geometry'!$B$65
Name I_2c: 'Geometry'!$B$66
Name I_2v: 'Geometry'!$B$67

Sheet README
A1: SPHX_EQV — 쉐브론 전열판 등가 판 계산 시트 (C-2)
A3: 목적: 원호+접선 주름 단면의 치수와 재료를 입력하면 등가 직교이방성 판 강성(채택식), 등가 두께, ±β 영역 강성, ANSYS 절 입력 문자열,
A4: 하중 케이스에 대한 능선(산·골) 응력과 허용응력 판정을 수식으로 계산한다. 파이썬 모듈 calc/plate_model.py 와 같은 로직이다.
A6: 사용법
A7: 1. 'Input' 시트의 노란 셀(파란 글씨)만 채운다. 나머지 시트는 전부 수식이다 (검정 = 수식, 녹색 = 다른 시트 참조).
A8: 2. 단면 입력 모드: A = R_c(,R_v) 입력 → 플랭크 각 α 를 Newton 반복으로 계산 / B = α 입력, R_c=R_v 계산.
A9: 3. 'Geometry' 상단 경고 행과 'Check' 시트(파이썬 대조)를 확인한다. Check 의 오차는 기본값 입력에서만 의미가 있다.
A10: 4. 'Rotation' 시트 하단의 SSPA/SSPD/SSPE/SSPM 문자열을 ANSYS 입력파일에 복사한다 (비틀림 규약은 E-1 확인 전까지 'verify').
A11: 5. 'Stress' 시트에 판축 또는 국부축 합력을 넣으면 산·골 4개 표면점의 응력과 최대 von Mises, 허용응력 비가 나온다.
A13: 범위·한계
A14: - 단면은 원호+접선(arc_tangent)만. 사인형/사다리꼴/반원 단면은 파이썬 모듈 사용.
A15: - 응력은 산(crest)·골(valley) 위치만 복원한다. 6개 단위 하중 모두에서 최대 응력이 산 또는 골에 생기지만, 플랭크 분포는 파이썬 전용.
... A22: 생성: calc/make_excel_sheet.py (재생성 시 이 파일을 덮어쓴다 — 수정은 생성기에서).

Sheet Input
A1: 입력 (노란 셀만 편집)
A4: 판 식별
A5: 항목 | B5: 값 | C5: 단위 | D5: 비고 / 수식 근거
A6: 판 식별자 | B6: SPHX-example | D6: 도면 번호 등
A7: 값 출처 | B7: assumed defaults (docs/05 §5) | D7: 예시값은 05 §5 가정 기본값 — 실제 도면값으로 교체
A9: 단면 (docs/05 §2.1, 중앙면 기준)
A10: 항목 | B10: 값 | C10: 단위 | D10: 비고 / 수식 근거
A11: 피치 p | B11: 9 | C11: mm | D11: 능선 수직 산-산 거리 (pitch_reference 에 따라 환산)
A12: 깊이 H | B12: 3.2 | C12: mm | D12: 산-골 높이차 (dims_reference 에 따라 환산)
A13: 공칭 두께 t | B13: 0.6 | C13: mm
A14: 단면 입력 모드 | B14: A | D14: A: R_c(,R_v) 입력 → α 계산 | B: α 입력 → R_c=R_v 계산
A15: 산 원호 반경 R_c | B15: 1.5 | C15: mm | D15: 모드 A. 외면 반경으로 측정했으면 R_o − t/2 로 환산해 기입
A16: 골 원호 반경 R_v | C16: mm | D16: 모드 A. 비우면 R_c 와 같게 처리
A17: 플랭크 각 α (입력) | C17: ° | D17: 모드 B 전용
A18: 치수 기준 dims_reference | B18: mid | D18: mid: 중앙면 | outer: 외면 (H = H_in − t 로 환산)
A19: 피치 기준 pitch_reference | B19: normal | D19: normal: 능선 수직 | axis: x_p 방향 측정 (p = p_in·cosβ)
A21: 쉐브론 (docs/05 §2.2)
A22: 항목 | B22: 값 | C22: 단위 | D22: 비고 / 수식 근거
A23: 쉐브론 각 β (입력) | B23: 60 | C23: °
A24: β 기준 beta_reference | B24: flow | D24: flow: 유동축 기준 | horizontal: 수평 기준 (β = 90 − 입력)
A26: 재료 (docs/05 §2.5)
A27: 항목 | B27: 값 | C27: 단위 | D27: 비고 / 수식 근거
A28: 재질 | B28: SA-240 316L
A29: 탄성계수 E | B29: 193000 | C29: MPa | D29: 설계온도 값 사용
A30: 포아송비 ν | B30: 0.3
A31: 밀도 ρ | B31: 7.9e-09 | C31: tonne/mm³ | D31: SSPM 입력용
A32: 성형 후 최소 두께 t_min | C32: mm | D32: 비우면 공칭 t 사용 (경고 표시)
A33: 부식 여유 CA | B33: 0 | C33: mm
A34: 허용응력 S_allow | C34: MPa | D34: 설계코드·온도 기준. 비우면 판정 생략
A36: 하중 케이스 (docs/10 §2.2) — 합력은 별도 산정값
A37: 항목 | B37: 값 | C37: 단위 | D37: 비고 / 수식 근거
A38: 케이스 이름 | B38: plate-axis My (right zone)
A39: 합력 좌표축 axes | B39: plate | D39: plate: 판축 (x_p, y_p) | local: 국부축 (x ⊥ 능선)
A40: 영역 zone | B40: right | D40: right: θ = −β | left: θ = +β (plate 축일 때만 사용)
A41: N_x (또는 N_xp) | B41: 0 | C41: N/mm
A42: N_y (또는 N_yp) | B42: 0 | C42: N/mm
A43: N_xy | B43: 0 | C43: N/mm
A44: M_x (또는 M_xp) | B44: 0 | C44: N·mm/mm
A45: M_y (또는 M_yp) | B45: 100 | C45: N·mm/mm
A46: M_xy | B46: 0 | C46: N·mm/mm | D46: 공학 비틀림 κ_xy 에 대응 (M_xy = D66·2κ_xy)
...

Sheet Geometry
A1: 형상 전처리·파생량 (docs/05 §3, 원호+접선 폐형식)
A4: 전처리 (표기 기준 → 계산 기준, docs/10 §2.1)
A5: 항목 | B5: 값 | C5: 단위 | D5: 비고 / 수식 근거
A6: β (유동축 기준) | B6: =IF(in_betaref="horizontal",90-in_beta,in_beta) | C6: ° | D6: beta_reference=horizontal → 90 − 입력
A7: β [rad] | B7: =RADIANS(beta_deg) | C7: rad
A8: 피치 p (능선 수직) | B8: =IF(in_pitchref="axis",in_p*COS(beta),in_p) | C8: mm | D8: pitch_reference=axis → p_in·cosβ
A9: 깊이 H (중앙면) | B9: =IF(in_dims="outer",in_H-in_t,in_H) | C9: mm | D9: dims_reference=outer → H_in − t
A10: 계산 두께 h = t_calc | B10: =IF(ISBLANK(in_tmin),in_t,in_tmin)-in_CA | C10: mm | D10: t_min(없으면 t) − CA. 강성·응력 모두 이 값 사용
A11: 반피치 c = p/2 | B11: =p_/2 | C11: mm
A12: 반깊이 f = H/2 | B12: =H_mid/2 | C12: mm
A14: 원호+접선 단면 해 (모드 A: Newton 반복 / 모드 B: 선형)
A15: 항목 | B15: 값 | C15: 단위 | D15: 비고 / 수식 근거
A16: R_c (모드 A) | B16: =in_Rc | C16: mm
A17: R_v (모드 A) | B17: =IF(ISBLANK(in_Rv),in_Rc,in_Rv) | C17: mm | D17: 비우면 R_c
A18: R_s = R_c + R_v | B18: =Rc_in+Rv_in | C18: mm
A19: α 상한 (T_L ≥ 0) | B19: =MIN(ASIN(MIN(1,c_/Rs)),ACOS(MAX(-1,1-H_mid/Rs)),PI()/2)-0.000001 | C19: rad | D19: 수평식·수직식에서 T_L ≥ 0 이 되는 α 범위의 상한
A20: Newton 반복: F(α) = R_s(1−cosα) + (c − R_s sinα)·tanα − H = 0, F'(α) = (c − R_s sinα)/cos²α. 각 반복값은 (0.001, a_hi) 로 제한.
A21: 반복 n | B21: α_n [rad] | C21: F(α_n) | D21: F'(α_n)
A22: 0 | B22: =MIN(a_hi,MAX(0.001,ATAN(H_mid/MAX(c_-Rs*0.5,0.001)))) | C22: =Rs*(1-COS($B$22))+(c_-Rs*SIN($B$22))*TAN($B$22)-H_mid | D22: =(c_-Rs*SIN($B$22))/COS($B$22)^2
A23: 1 | B23: =MIN(a_hi,MAX(0.001,$B$22-$C$22/$D$22)) | C23: =Rs*(1-COS($B$23))+(c_-Rs*SIN($B$23))*TAN($B$23)-H_mid | D23: =(c_-Rs*SIN($B$23))/COS($B$23)^2
A24: 2 | B24: =MIN(a_hi,MAX(0.001,$B$23-$C$23/$D$23)) | C24: =Rs*(1-COS($B$24))+(c_-Rs*SIN($B$24))*TAN($B$24)-H_mid | D24: =(c_-Rs*SIN($B$24))/COS($B$24)^2
A25: 3 | B25: =MIN(a_hi,MAX(0.001,$B$24-$C$24/$D$24)) | C25: =Rs*(1-COS($B$25))+(c_-Rs*SIN($B$25))*TAN($B$25)-H_mid | D25: =(c_-Rs*SIN($B$25))/COS($B$25)^2
A26: 4 | B26: =MIN(a_hi,MAX(0.001,$B$25-$C$25/$D$25)) | C26: =Rs*(1-COS($B$26))+(c_-Rs*SIN($B$26))*TAN($B$26)-H_mid | D26: =(c_-Rs*SIN($B$26))/COS($B$26)^2
A27: 5 | B27: =MIN(a_hi,MAX(0.001,$B$26-$C$26/$D$26)) | C27: =Rs*(1-COS($B$27))+(c_-Rs*SIN($B$27))*TAN($B$27)-H_mid | D27: =(c_-Rs*SIN($B$27))/COS($B$27)^2
A28: 6 | B28: =MIN(a_hi,MAX(0.001,$B$27-$C$27/$D$27)) | C28: =Rs*(1-COS($B$28))+(c_-Rs*SIN($B$28))*TAN($B$28)-H_mid | D28: =(c_-Rs*SIN($B$28))/COS($B$28)^2
A29: 7 | B29: =MIN(a_hi,MAX(0.001,$B$28-$C$28/$D$28)) | C29: =Rs*(1-COS($B$29))+(c_-Rs*SIN($B$29))*TAN($B$29)-H_mid | D29: =(c_-Rs*SIN($B$29))/COS($B$29)^2
A30: 8 | B30: =MIN(a_hi,MAX(0.001,$B$29-$C$29/$D$29)) | C30: =Rs*(1-COS($B$30))+(c_-Rs*SIN($B$30))*TAN($B$30)-H_mid | D30: =(c_-Rs*SIN($B$30))/COS($B$30)^2
A31: 9 | B31: =MIN(a_hi,MAX(0.001,$B$30-$C$30/$D$30)) | C31: =Rs*(1-COS($B$31))+(c_-Rs*SIN($B$31))*TAN($B$31)-H_mid | D31: =(c_-Rs*SIN($B$31))/COS($B$31)^2
A32: 10 | B32: =MIN(a_hi,MAX(0.001,$B$31-$C$31/$D$31)) | C32: =Rs*(1-COS($B$32))+(c_-Rs*SIN($B$32))*TAN($B$32)-H_mid | D32: =(c_-Rs*SIN($B$32))/COS($B$32)^2
A33: 11 | B33: =MIN(a_hi,MAX(0.001,$B$32-$C$32/$D$32)) | C33: =Rs*(1-COS($B$33))+(c_-Rs*SIN($B$33))*TAN($B$33)-H_mid | D33: =(c_-Rs*SIN($B$33))/COS($B$33)^2
A34: 12 | B34: =MIN(a_hi,MAX(0.001,$B$33-$C$33/$D$33)) | C34: =Rs*(1-COS($B$34))+(c_-Rs*SIN($B$34))*TAN($B$34)-H_mid | D34: =(c_-Rs*SIN($B$34))/COS($B$34)^2
A35: 13 | B35: =MIN(a_hi,MAX(0.001,$B$34-$C$34/$D$34)) | C35: =Rs*(1-COS($B$35))+(c_-Rs*SIN($B$35))*TAN($B$35)-H_mid | D35: =(c_-Rs*SIN($B$35))/COS($B$35)^2
A36: 14 | B36: =MIN(a_hi,MAX(0.001,$B$35-$C$35/$D$35)) | C36: =Rs*(1-COS($B$36))+(c_-Rs*SIN($B$36))*TAN($B$36)-H_mid | D36: =(c_-Rs*SIN($B$36))/COS($B$36)^2
A37: 15 | B37: =MIN(a_hi,MAX(0.001,$B$36-$C$36/$D$36)) | C37: =Rs*(1-COS($B$37))+(c_-Rs*SIN($B$37))*TAN($B$37)-H_mid | D37: =(c_-Rs*SIN($B$37))/COS($B$37)^2
A38: 16 | B38: =MIN(a_hi,MAX(0.001,$B$37-$C$37/$D$37)) | C38: =Rs*(1-COS($B$38))+(c_-Rs*SIN($B$38))*TAN($B$38)-H_mid | D38: =(c_-Rs*SIN($B$38))/COS($B$38)^2
A39: 17 | B39: =MIN(a_hi,MAX(0.001,$B$38-$C$38/$D$38)) | C39: =Rs*(1-COS($B$39))+(c_-Rs*SIN($B$39))*TAN($B$39)-H_mid | D39: =(c_-Rs*SIN($B$39))/COS($B$39)^2
A40: 18 | B40: =MIN(a_hi,MAX(0.001,$B$39-$C$39/$D$39)) | C40: =Rs*(1-COS($B$40))+(c_-Rs*SIN($B$40))*TAN($B$40)-H_mid | D40: =(c_-Rs*SIN($B$40))/COS($B$40)^2
A41: 19 | B41: =MIN(a_hi,MAX(0.001,$B$40-$C$40/$D$40)) | C41: =Rs*(1-COS($B$41))+(c_-Rs*SIN($B$41))*TAN($B$41)-H_mid | D41: =(c_-Rs*SIN($B$41))/COS($B$41)^2
A42: 20 | B42: =MIN(a_hi,MAX(0.001,$B$41-$C$41/$D$41)) | C42: =Rs*(1-COS($B$42))+(c_-Rs*SIN($B$42))*TAN($B$42)-H_mid | D42: =(c_-Rs*SIN($B$42))/COS($B$42)^2
A44: α (모드 A 해) | B44: =$B$42 | C44: rad | D44: Newton 20회 최종값
...

Sheet Stiffness
A1: 국부축 등가 강성 — 채택식 (docs/06 §2, Ye 2014 Eq. 19) 및 등가 두께 (docs/09 §1)
A4: 재료
A5: 항목 | B5: 값 | C5: 단위 | D5: 비고 / 수식 근거
A6: E | B6: =in_E | C6: MPa
A7: ν | B7: =in_nu
A8: G = E/(2(1+ν)) | B8: =E_/(2*(1+nu_)) | C8: MPa
A9: Q = E/(1−ν²) | B9: =E_/(1-nu_^2) | C9: MPa | D9: 평면응력 강성
A11: 채택식 A (막) [N/mm], D (굽힘) [N·mm] — x ⊥ 능선, y ∥ 능선
A12: 항목 | B12: 값 | C12: 단위 | D12: 비고 / 수식 근거
A13: A11 | B13: =E_*h_calc^3/((1-nu_^2)*(12*J_2+h_calc^2*J_1)) | C13: N/mm | D13: E h³ / ((1−ν²)(12J2 + h²J1))
A14: A12 | B14: =nu_*A_11 | C14: N/mm | D14: ν A11
A15: A22 | B15: =E_*h_calc*lam+nu_^2*A_11 | C15: N/mm | D15: E h λ + ν² A11
A16: A66 | B16: =G_*h_calc/lam | C16: N/mm | D16: G h / λ
A17: D11 | B17: =E_*h_calc^3/(12*(1-nu_^2)*lam) | C17: N·mm | D17: E h³ / (12(1−ν²) λ)
A18: D12 | B18: =nu_*D_11 | C18: N·mm | D18: ν D11
A19: D22 | B19: =E_*h_calc*J_2+E_*h_calc^3*J_1/12+nu_^2*D_11 | C19: N·mm | D19: E h J2 + E h³ J1/12 + ν² D11
A20: D66 | B20: =G_*h_calc^3*lam/12 | C20: N·mm | D20: G h³ λ / 12 (κ_xy 공학 비틀림 관례: M_xy = D66·2κ_xy)
A21: A22/A11 | B21: =A_22/A_11 | D21: 직교이방성 비
A22: D22/D11 | B22: =D_22/D_11
A23: A66/A11 | B23: =A_66/A_11
A25: 모델 비교 (채택식 대비 %, docs/06 §3)
A26: 항목 | B26: 값 | C26: 단위 | D26: 비고 / 수식 근거
A27: Xia 2012 D22 (Dirichlet 상한) | B27: =((E_*h_calc*J_2+E_*h_calc^3*J_1/12)/(1-nu_^2)/D_22-1)*100 | C27: % | D27: 1/(1−ν²) 과대
A28: Lang & Su 2022 A22 | B28: =((nu_^2*A_11+(1-nu_^2)*E_*h_calc*lam)/A_22-1)*100 | C28: % | D28: 평판 극한 불환원
A29: Lang & Su 2022 A11 | B29: =((E_*h_calc^3/(12*J_2*(1-nu_^2)+h_calc^2*J_1))/A_11-1)*100 | C29: %
A30: Ye 얕은 주름식 A11 | B30: =((E_*h_calc^3/(12*(1-nu_^2)*J_2))/A_11-1)*100 | C30: % | D30: J1 항 생략
A31: Ye 얕은 주름식 D22 | B31: =((E_*h_calc*J_2)/D_22-1)*100 | C31: %
A33: 등가 두께 (docs/09 §1)
A34: 항목 | B34: 값 | C34: 단위 | D34: 비고 / 수식 근거
A35: t_b = √(12 D11/A11) | B35: =SQRT(12*D_11/A_11) | C35: mm | D35: 굽힘–막 정합 (11/12/22 공통)
A36: √(12 D22/A22) (검사) | B36: =SQRT(12*D_22/A_22) | C36: mm | D36: t_b 와 같아야 함
A37: t_s = √(12 D66/A66) = hλ | B37: =SQRT(12*D_66/A_66) | C37: mm | D37: 전단–비틀림 정합
A38: t_m = hλ | B38: =h_calc*lam | C38: mm | D38: 질량·전개면적
A40: 균질 직교이방성 단일층 (t_e = t_b, 간이 검토용 — 조립체 FE 에는 GENS 절 사용)
A41: 항목 | B41: 값 | C41: 단위 | D41: 비고 / 수식 근거
A42: E_x | B42: =(A_11*A_22-A_12^2)/(A_22*t_b) | C42: MPa
A43: E_y | B43: =(A_11*A_22-A_12^2)/(A_11*t_b) | C43: MPa
A44: ν_xy | B44: =A_12/A_22
A45: G_xy (A66 기준) | B45: =A_66/t_b | C45: MPa | D45: D66 오차 → 아래
A46: → D66 재현 오차 | B46: =(GA_h*t_b^3/12/D_66-1)*100 | C46: %
...

Sheet Rotation
A1: 판축 영역 강성 (docs/07) 및 ANSYS preintegrated general shell section 입력 (docs/09 §2)
A4: 회전각
A5: 항목 | B5: 값 | C5: 단위 | D5: 비고 / 수식 근거
A6: 우측 영역 θ_R = −β | B6: =-beta | C6: rad | D6: 능선이 +β 방향인 영역
A7: 좌측 영역 θ_L = +β | B7: =beta | C7: rad
A8: Q̄ 폐형식 (Jones 1975): m=cosθ, n=sinθ. 11: q11m⁴+2(q12+2q66)n²m²+q22n⁴ ; 22: q11n⁴+…+q22m⁴ ; 12: (q11+q22−4q66)n²m²+q12(n⁴+m⁴)
A9: 66: (q11+q22−2q12−2q66)n²m²+q66(n⁴+m⁴) ; 16: (q11−q12−2q66)nm³+(q12−q22+2q66)n³m ; 26: (q11−q12−2q66)n³m+(q12−q22+2q66)nm³
A11: 성분 | B11: 우측 영역 (θ=−β) | C11: 좌측 영역 (θ=+β) | D11: 비고
A12: A11 | B12: =A_11*COS(th_R)^4+2*(A_12+2*A_66)*SIN(th_R)^2*COS(th_R)^2+A_22*SIN(th_R)^4 | C12: =A_11*COS(th_L)^4+2*(A_12+2*A_66)*SIN(th_L)^2*COS(th_L)^2+A_22*SIN(th_L)^4 | D12: N/mm
A13: A22 | B13: =A_11*SIN(th_R)^4+2*(A_12+2*A_66)*SIN(th_R)^2*COS(th_R)^2+A_22*COS(th_R)^4 | C13: =A_11*SIN(th_L)^4+2*(A_12+2*A_66)*SIN(th_L)^2*COS(th_L)^2+A_22*COS(th_L)^4 | D13: N/mm
A14: A12 | B14: =(A_11+A_22-4*A_66)*SIN(th_R)^2*COS(th_R)^2+A_12*(SIN(th_R)^4+COS(th_R)^4) | C14: =(A_11+A_22-4*A_66)*SIN(th_L)^2*COS(th_L)^2+A_12*(SIN(th_L)^4+COS(th_L)^4) | D14: N/mm
A15: A66 | B15: =(A_11+A_22-2*A_12-2*A_66)*SIN(th_R)^2*COS(th_R)^2+A_66*(SIN(th_R)^4+COS(th_R)^4) | C15: =(A_11+A_22-2*A_12-2*A_66)*SIN(th_L)^2*COS(th_L)^2+A_66*(SIN(th_L)^4+COS(th_L)^4) | D15: N/mm
A16: A16 | B16: =(A_11-A_12-2*A_66)*SIN(th_R)*COS(th_R)^3+(A_12-A_22+2*A_66)*SIN(th_R)^3*COS(th_R) | C16: =(A_11-A_12-2*A_66)*SIN(th_L)*COS(th_L)^3+(A_12-A_22+2*A_66)*SIN(th_L)^3*COS(th_L) | D16: N/mm
A17: A26 | B17: =(A_11-A_12-2*A_66)*SIN(th_R)^3*COS(th_R)+(A_12-A_22+2*A_66)*SIN(th_R)*COS(th_R)^3 | C17: =(A_11-A_12-2*A_66)*SIN(th_L)^3*COS(th_L)+(A_12-A_22+2*A_66)*SIN(th_L)*COS(th_L)^3 | D17: N/mm
A18: D11 | B18: =D_11*COS(th_R)^4+2*(D_12+2*D_66)*SIN(th_R)^2*COS(th_R)^2+D_22*SIN(th_R)^4 | C18: =D_11*COS(th_L)^4+2*(D_12+2*D_66)*SIN(th_L)^2*COS(th_L)^2+D_22*SIN(th_L)^4 | D18: N·mm
A19: D22 | B19: =D_11*SIN(th_R)^4+2*(D_12+2*D_66)*SIN(th_R)^2*COS(th_R)^2+D_22*COS(th_R)^4 | C19: =D_11*SIN(th_L)^4+2*(D_12+2*D_66)*SIN(th_L)^2*COS(th_L)^2+D_22*COS(th_L)^4 | D19: N·mm
A20: D12 | B20: =(D_11+D_22-4*D_66)*SIN(th_R)^2*COS(th_R)^2+D_12*(SIN(th_R)^4+COS(th_R)^4) | C20: =(D_11+D_22-4*D_66)*SIN(th_L)^2*COS(th_L)^2+D_12*(SIN(th_L)^4+COS(th_L)^4) | D20: N·mm
A21: D66 | B21: =(D_11+D_22-2*D_12-2*D_66)*SIN(th_R)^2*COS(th_R)^2+D_66*(SIN(th_R)^4+COS(th_R)^4) | C21: =(D_11+D_22-2*D_12-2*D_66)*SIN(th_L)^2*COS(th_L)^2+D_66*(SIN(th_L)^4+COS(th_L)^4) | D21: N·mm
A22: D16 | B22: =(D_11-D_12-2*D_66)*SIN(th_R)*COS(th_R)^3+(D_12-D_22+2*D_66)*SIN(th_R)^3*COS(th_R) | C22: =(D_11-D_12-2*D_66)*SIN(th_L)*COS(th_L)^3+(D_12-D_22+2*D_66)*SIN(th_L)^3*COS(th_L) | D22: N·mm
A23: D26 | B23: =(D_11-D_12-2*D_66)*SIN(th_R)^3*COS(th_R)+(D_12-D_22+2*D_66)*SIN(th_R)*COS(th_R)^3 | C23: =(D_11-D_12-2*D_66)*SIN(th_L)^3*COS(th_L)+(D_12-D_22+2*D_66)*SIN(th_L)*COS(th_L)^3 | D23: N·mm
A25: 횡전단·질량 (Mindlin 쉘 보조량, docs/09 §2 항 5–6)
A26: 항목 | B26: 값 | C26: 단위 | D26: 비고 / 수식 근거
A27: 횡전단 E11 = E22 = (5/6) G h λ | B27: =5/6*G_*h_calc*lam | C27: N/mm | D27: 1차 추정 — E단계 ×0.1/×10 감도 확인
A28: 단위두께 가정 밀도 = ρ h λ | B28: =in_rho*h_calc*lam | C28: tonne/mm² | D28: SSPM
A30: ANSYS APDL 문자열 (복사용; 인자 순서 SSPA/SSPD: 11,21,31,22,32,33 — 3 = xy; 판축 요소좌표계)
A31: 항목 | B31: 값 | C31: 단위 | D31: 비고 / 수식 근거
A32: 우측 SECTYPE | B32: ="SECTYPE,11,GENS,,SPHX_R ! zone R, theta = -beta, element CS = plate axes"
A33: 우측 SSPA | B33: ="SSPA,"&TEXT(A_11_R,"0.000000E+00")&","&TEXT(A_12_R,"0.000000E+00")&","&TEXT(A_16_R,"0.000000E+00")&","&TEXT(A_22_R,"0.000000E+00")&","&TEXT(A_26_R,"0.000000E+00")&","&TEXT(A_66_R,"0.000000E+00") | D33: A11,A21,A31,A22,A32,A33
A34: 우측 SSPB | B34: ="SSPB,0,0,0,0,0,0 ! B = 0 (symmetric section)"
A35: 우측 SSPD | B35: ="SSPD,"&TEXT(D_11_R,"0.000000E+00")&","&TEXT(D_12_R,"0.000000E+00")&","&TEXT(D_16_R,"0.000000E+00")&","&TEXT(D_22_R,"0.000000E+00")&","&TEXT(D_26_R,"0.000000E+00")&","&TEXT(D_66_R,"0.000000E+00")&" ! D33/16/26 twist convention: verify (E-1)" | D35: D11,D21,D31,D22,D32,D33
A36: 우측 SSPE | B36: ="SSPE,"&TEXT(E_ts,"0.000000E+00")&",0,"&TEXT(E_ts,"0.000000E+00")&" ! transverse shear estimate"
A37: 우측 SSPM | B37: ="SSPM,"&TEXT(dens_a,"0.000000E+00")&" ! density assuming unit thickness = rho*h*lambda"
A39: 좌측 SECTYPE | B39: ="SECTYPE,12,GENS,,SPHX_L ! zone L, theta = +beta, element CS = plate axes"
A40: 좌측 SSPA | B40: ="SSPA,"&TEXT(A_11_L,"0.000000E+00")&","&TEXT(A_12_L,"0.000000E+00")&","&TEXT(A_16_L,"0.000000E+00")&","&TEXT(A_22_L,"0.000000E+00")&","&TEXT(A_26_L,"0.000000E+00")&","&TEXT(A_66_L,"0.000000E+00") | D40: A11,A21,A31,A22,A32,A33
A41: 좌측 SSPB | B41: ="SSPB,0,0,0,0,0,0 ! B = 0 (symmetric section)"
A42: 좌측 SSPD | B42: ="SSPD,"&TEXT(D_11_L,"0.000000E+00")&","&TEXT(D_12_L,"0.000000E+00")&","&TEXT(D_16_L,"0.000000E+00")&","&TEXT(D_22_L,"0.000000E+00")&","&TEXT(D_26_L,"0.000000E+00")&","&TEXT(D_66_L,"0.000000E+00")&" ! D33/16/26 twist convention: verify (E-1)" | D42: D11,D21,D31,D22,D32,D33
A43: 좌측 SSPE | B43: ="SSPE,"&TEXT(E_ts,"0.000000E+00")&",0,"&TEXT(E_ts,"0.000000E+00")&" ! transverse shear estimate"
A44: 좌측 SSPM | B44: ="SSPM,"&TEXT(dens_a,"0.000000E+00")&" ! density assuming unit thickness = rho*h*lambda"

Sheet Stress
A1: 하중 케이스 → 국부축 합력 → VAM 복원 (Ye 2014 Eq. 14, 20; docs/09 §3) — 산·골 응력과 판정
A4: 하중 케이스 합력 → 국부축 (transform.resultants_to_local, T_σ)
A5: 항목 | B5: 값 | C5: 단위 | D5: 비고 / 수식 근거
A6: θ (plate 축일 때) | B6: =IF(lc_axes="plate",IF(lc_zone="right",-beta,beta),0) | C6: rad | D6: local 축이면 0 (변환 없음)
A7: m = cosθ | B7: =COS(th_lc)
A8: n = sinθ | B8: =SIN(th_lc)
A9: N_x (국부) | B9: =lc_Nx*mm_^2+lc_Ny*nn_^2+2*lc_Nxy*mm_*nn_ | C9: N/mm | D9: T_σ 1행: m², n², 2mn
A10: N_y (국부) | B10: =lc_Nx*nn_^2+lc_Ny*mm_^2-2*lc_Nxy*mm_*nn_ | C10: N/mm | D10: n², m², −2mn
A11: N_xy (국부) | B11: =-lc_Nx*mm_*nn_+lc_Ny*mm_*nn_+lc_Nxy*(mm_^2-nn_^2) | C11: N/mm | D11: −mn, mn, m²−n²
A12: M_x (국부) | B12: =lc_Mx*mm_^2+lc_My*nn_^2+2*lc_Mxy*mm_*nn_ | C12: N·mm/mm
A13: M_y (국부) | B13: =lc_Mx*nn_^2+lc_My*mm_^2-2*lc_Mxy*mm_*nn_ | C13: N·mm/mm
A14: M_xy (국부) | B14: =-lc_Mx*mm_*nn_+lc_My*mm_*nn_+lc_Mxy*(mm_^2-nn_^2) | C14: N·mm/mm
A16: 거시 변형률 (채택식 역행렬)
A17: 항목 | B17: 값 | C17: 단위 | D17: 비고 / 수식 근거
A18: det A (11,22 블록) | B18: =A_11*A_22-A_12^2
A19: ε_xx | B19: =(A_22*Nx-A_12*Ny)/detA
A20: ε_yy | B20: =(-A_12*Nx+A_11*Ny)/detA
A21: γ_xy = 2ε_xy | B21: =Nxy/A_66
A22: det D (11,22 블록) | B22: =D_11*D_22-D_12^2
A23: κ_xx | B23: =(D_22*Mx-D_12*My)/detD | C23: 1/mm
A24: κ_yy | B24: =(-D_12*Mx+D_11*My)/detD | C24: 1/mm
A25: κ_xy (텐서) | B25: =Mxy/(2*D_66) | C25: 1/mm | D25: M_xy = D66·2κ_xy
A27: VAM 복원 상수 (대칭 단면)
A28: 항목 | B28: 값 | C28: 단위 | D28: 비고 / 수식 근거
A29: 𝒞 = −(12J2/h² + J1) | B29: =-(12*J_2/h_calc^2+J_1)
A30: c1 = −(ε_xx + ν ε_yy)/𝒞 | B30: =-(exx+nu_*eyy)/CC
A31: c4 = (κ_xx + ν κ_yy)/λ | B31: =(kxx+nu_*kyy)/lam | C31: 1/mm
A32: c_h(산) = 1 + h²/(48R_c²) | B32: =1+h_calc^2/(48*Rc^2) | D32: 두께 보정
A33: c_h(골) = 1 + h²/(48R_v²) | B33: =1+h_calc^2/(48*Rv^2)
A34: ⟨√a/c_h⟩·2c = 2R_cα/c_h,c + 2T_L + 2R_vα/c_h,v | B34: =2*Rc*alpha/ch_c+2*TL+2*Rv*alpha/ch_v | C34: mm | D34: 1주기 적분
A35: α1 = 2c / 위 | B35: =2*c_/inva1
A36: c2 = α1 γ_xy | B36: =alpha1*gxy
A38: 산(crest, z=+f, κ=−1/R_c) 과 골(valley, z=−f, κ=+1/R_v) 의 물리 변형률 (√a = 1)
A39: 항목 | B39: 값 | C39: 단위 | D39: 비고 / 수식 근거
A40: 량 | B40: 산 (crest) | C40: 골 (valley) | D40: 식
A41: ε_s | B41: =c_1-nu_*(eyy+f_*kyy) | C41: =c_1-nu_*(eyy-f_*kyy) | D41: γ11/a = c1√a − νa(ε_yy + zκ_yy)
A42: ε_y | B42: =eyy+f_*kyy | C42: =eyy-f_*kyy | D42: γ22 = ε_yy + zκ_yy
A43: γ_sy | B43: =(c_2+h_calc^2*kxy/(12*Rc))/ch_c | C43: =(c_2-h_calc^2*kxy/(12*Rv))/ch_v | D43: 2γ12/√a = (√a c2 − h² z'' κ_xy/(12a))/c_h, z''=∓1/R
A44: κ_s | B44: =12*c_1*f_/h_calc^2+c_4-nu_*kyy | C44: =-12*c_1*f_/h_calc^2+c_4-nu_*kyy | D44: ρ11/a = 12c1 z/h² + c4 − νκ_yy/√a
A45: κ_y | B45: =kyy | C45: =kyy | D45: ρ22 = κ_yy/√a
...

Sheet Check
A1: 파이썬 대조 (docs/example_report/results.json, 가정 기본값 입력에서만 유효)
A4: 기본값: p=9, H=3.2, t=0.6, R_c=1.5, β=60°, E=193000, ν=0.3, 하중 케이스 plate My=100 (right)
A5: 항목 | B5: 엑셀 | C5: 파이썬 (하드코딩 참조값) | D5: 상대오차 | E5: 출처
A6: α [°] | B6: =alpha_deg | C6: 44.3046 | D6: =IF(ABS($C$6)>1E-9,ABS($B$6/$C$6-1),ABS($B$6-$C$6)) | E6: geometry.arc_tangent
A7: T_L | B7: =TL | C7: 3.3600595 | D7: =IF(ABS($C$7)>1E-9,ABS($B$7/$C$7-1),ABS($B$7-$C$7)) | E7: 〃
A8: l | B8: =l_ | C8: 5.6798429 | D8: =IF(ABS($C$8)>1E-9,ABS($B$8/$C$8-1),ABS($B$8-$C$8)) | E8: 〃
A9: I1 | B9: =I_1 | C9: 7.2609553 | D9: =IF(ABS($C$9)>1E-9,ABS($B$9/$C$9-1),ABS($B$9-$C$9)) | E9: 〃
A10: I2 | B10: =I_2 | C10: 12.981692 | D10: =IF(ABS($C$10)>1E-9,ABS($B$10/$C$10-1),ABS($B$10-$C$10)) | E10: 〃
A11: A11 | B11: =A_11 | C11: 2602.9916 | D11: =IF(ABS($C$11)>1E-9,ABS($B$11/$C$11-1),ABS($B$11-$C$11)) | E11: stiffness.adopted
A12: A22 | B12: =A_22 | C12: 146395.56 | D12: =IF(ABS($C$12)>1E-9,ABS($B$12/$C$12-1),ABS($B$12-$C$12)) | E12: 〃
A13: A66 | B13: =A_66 | C13: 35286.729 | D13: =IF(ABS($C$13)>1E-9,ABS($B$13/$C$13-1),ABS($B$13-$C$13)) | E13: 〃
A14: D11 | B14: =D_11 | C14: 3024.5767 | D14: =IF(ABS($C$14)>1E-9,ABS($B$14/$C$14-1),ABS($B$14-$C$14)) | E14: 〃
A15: D22 | B15: =D_22 | C15: 170106.05 | D15: =IF(ABS($C$15)>1E-9,ABS($B$15/$C$15-1),ABS($B$15-$C$15)) | E15: 〃
A16: D66 | B16: =D_66 | C16: 1686.4764 | D16: =IF(ABS($C$16)>1E-9,ABS($B$16/$C$16-1),ABS($B$16-$C$16)) | E16: 〃
A17: t_b | B17: =t_b | C17: 3.7341051 | D17: =IF(ABS($C$17)>1E-9,ABS($B$17/$C$17-1),ABS($B$17-$C$17)) | E17: equivalent_plate
A18: t_s | B18: =t_s | C18: 0.75731239 | D18: =IF(ABS($C$18)>1E-9,ABS($B$18/$C$18-1),ABS($B$18-$C$18)) | E18: 〃
A19: A11 우측 | B19: =A_11_R | C19: 109268.07 | D19: =IF(ABS($C$19)>1E-9,ABS($B$19/$C$19-1),ABS($B$19-$C$19)) | E19: transform.zone_stiffness
A20: A16 우측 | B20: =A_16_R | C20: 31812.9 | D20: =IF(ABS($C$20)>1E-9,ABS($B$20/$C$20-1),ABS($B$20-$C$20)) | E20: 〃
A21: A26 우측 | B21: =A_26_R | C21: 30451.109 | D21: =IF(ABS($C$21)>1E-9,ABS($B$21/$C$21-1),ABS($B$21-$C$21)) | E21: 〃
A22: D12 우측 | B22: =D_12_R | C22: 31764.242 | D22: =IF(ABS($C$22)>1E-9,ABS($B$22/$C$22-1),ABS($B$22-$C$22)) | E22: 〃
A23: D16 우측 | B23: =D_16_R | C23: 53989.421 | D23: =IF(ABS($C$23)>1E-9,ABS($B$23/$C$23-1),ABS($B$23-$C$23)) | E23: 〃
A24: D66 우측 | B24: =D_66_R | C24: 32543.346 | D24: =IF(ABS($C$24)>1E-9,ABS($B$24/$C$24-1),ABS($B$24-$C$24)) | E24: 〃
A25: M_x 국부 | B25: =Mx | C25: 75 | D25: =IF(ABS($C$25)>1E-9,ABS($B$25/$C$25-1),ABS($B$25-$C$25)) | E25: resultants_to_local
A26: M_xy 국부 | B26: =Mxy | C26: -43.30127 | D26: =IF(ABS($C$26)>1E-9,ABS($B$26/$C$26-1),ABS($B$26-$C$26)) | E26: 〃
A27: 산 외측 σ_s | B27: =Stress!$B$54 | C27: -1250 | D27: =IF(ABS($C$27)>1E-9,ABS($B$27/$C$27-1),ABS($B$27-$C$27)) | E27: ye_recovery (능선)
A28: 산 내측 σ_s | B28: =Stress!$C$54 | C28: 1250 | D28: =IF(ABS($C$28)>1E-9,ABS($B$28/$C$28-1),ABS($B$28-$C$28)) | E28: 〃
A29: 산 외측 σ_y | B29: =Stress!$B$55 | C29: -371.30672 | D29: =IF(ABS($C$29)>1E-9,ABS($B$29/$C$29-1),ABS($B$29-$C$29)) | E29: 〃
A30: 산 내측 σ_y | B30: =Stress!$C$55 | C30: 380.39787 | D30: =IF(ABS($C$30)>1E-9,ABS($B$30/$C$30-1),ABS($B$30-$C$30)) | E30: 〃
A31: 산 외측 τ | B31: =Stress!$B$56 | C31: -588.87182 | D31: =IF(ABS($C$31)>1E-9,ABS($B$31/$C$31-1),ABS($B$31-$C$31)) | E31: 〃
A32: 산 내측 τ | B32: =Stress!$C$56 | C32: 550.88009 | D32: =IF(ABS($C$32)>1E-9,ABS($B$32/$C$32-1),ABS($B$32-$C$32)) | E32: 〃
A33: 최대 von Mises | B33: =vm_max | C33: 1508.8225 | D33: =IF(ABS($C$33)>1E-9,ABS($B$33/$C$33-1),ABS($B$33-$C$33)) | E33: 파이썬 전 단면 최대 (산·골에서 발생)
A35: 최대 상대오차 | B35: =MAX($D$6:$D$33) | D35: 기본값 입력에서 1e-6 이하이면 시트 로직이 파이썬과 일치
A36: 판정 | B36: =IF(chk_max<0.000001,"일치","불일치 — 입력이 기본값과 다르거나 시트 수정됨")
A37: 참조값은 calc/plate_model.py 실행 결과(docs/example_report/results.json)를 생성 시점에 복사한 하드코딩 값이다 (파랑).
